Workbook

Sheet README
A1: AI Agents & Student Learning - Merged Meta-Analysis Dataset
A3: What this workbook contains
A4: 1. ES_Data - one row per effect size (treatment vs control) for every study: cognitive outcomes (knowledge-based, skill-based, higher-order thinking, cognitive load) and non-cognitive outcomes (learning dispositions, emotional functioning, self-management, social competence, curiosity, attitudes toward AI). Hedges' g, variance, SE, 95% CI, z, p and weights are live Excel formulas.
A5: 2. Study_Characteristics - one row per study (moderator coding: country, education level, discipline, AI agent type, teacher involvement, design, comparison, duration).
A6: 3. Correlational_Studies - survey/SEM studies that report correlations (r) or standardized paths (beta) between AI use and learning outcomes, converted to Fisher's z (kept separate from experimental SMDs).
A7: 4. Summary - random-effects (DerSimonian-Laird) pooled estimates by outcome domain, subgroup, AI agent type and education level, computed with formulas from ES_Data rows flagged 'Y' in 'Include in primary analysis'.
A8: 5. Screening_Log - every file you uploaded (49 papers/pages + 5 workbooks) with the eligibility decision and reason.
A9: 6. Data_Issues - discrepancies found while merging your workbooks and checking the papers (please verify these).
A10: 7. Coding_Scheme - definitions of every category and of the effect-size formulas.
A12: How to use / edit
A13: Blue text = hard-coded inputs taken from papers or your workbooks (edit these). Black text = formulas (do not overwrite). Green = values pulled from another sheet.
A14: To add a study: copy the last row of ES_Data, enter the descriptive statistics (tn, tmean, tsd, cn, cmean, csd) and set 'ES input type' to MSD. If a paper reports only t, F, z or a paired t, enter that statistic in 'Test statistic' and choose the matching input type.
... A21: - Rows from your original workbooks were kept as entered except for documented corrections (see Data_Issues). Values for studies whose full text you uploaded were re-extracted from the paper.

Sheet ES_Data
A1: ES_ID | B1: Study_ID | C1: Author (Year) | D1: Year | E1: Country | F1: Education level | G1: Academic discipline | H1: AI agent type (harmonized) | I1: AI agent / tool (as reported) | J1: Teacher involvement | K1: Research design | L1: Comparison condition | M1: Intervention duration W(S) | N1: Minutes (M) | O1: Duration category | P1: Outcome domain | Q1: Outcome category (subgroup) | R1: Curiosity dimension | S1: Outcome name | T1: Outcome measure | U1: Test phase | V1: tn | W1: tmean | X1: tsd | Y1: cn | Z1: cmean | AA1: csd | AB1: ES input type | AC1: Test statistic | AD1: Direction | AE1: Cohen's d | AF1: J (small-sample correction) | AG1: Hedges' g (_meta_es) | AH1: Variance | AI1: SE (_meta_se) | AJ1: 95% CI lower (_meta_cil) | AK1: 95% CI upper (_meta_ciu) | AL1: z-value | AM1: p-value | AN1: Total N (_meta_studysize) | AO1: Weight 1/v (_meta_weight) | AP1: Include in primary analysis (Y/N) | AQ1: Data source | AR1: Notes (table / page / issues) | AS1: w_inc | AT1: wg_inc | AU1: wg2_inc | AV1: w2_inc | AW1: g_inc | AX1: v_inc
A2: ES001 | B2: S001 | C2: Abdelghani et al. (2022) | D2: 2022 | E2: France | F2: Primary education | G2: Science / general knowledge (reading-based) | H2: Conversational AI / chatbot | I2: Conversational AI (pedagogical agent) - 'Kids Ask' incentive conversational agent (semantic cues) | J2: No | K2: Pseudo-randomized controlled experiment, 2 groups | L2: Neutral conversational agent (no cues) | M2: 4 sessions in 1 week | N2: 75 per session | O2: Less than 1 week | P2: Cognitive | Q2: Higher-order thinking skills | S2: Percentage of divergent questions generated | T2: Divergent QA % during training (mixed ANOVA) | U2: Post-test | V2: 25 | Y2: 26 | AB2: F | AC2: 17.87 | AD2: 1 | AE2: =IFERROR(IF(AB2="MSD",IF(COUNT(V2,W2,X2,Y2,Z2,AA2)<6,"",(W2-Z2)/SQRT(((V2-1)*X2^2+(Y2-1)*AA2^2)/(V2+Y2-2))*AD2),IF(AB2="t",AC2*SQRT(1/V2+1/Y2)*AD2,IF(AB2="F",SQRT(AC2)*SQRT(1/V2+1/Y2)*AD2,IF(AB2="z",2*(AC2/SQRT(V2+Y2))/SQRT(1-(AC2/SQRT(V2+Y2))^2)*AD2,IF(AB2="t_paired",AC2/SQRT(V2)*AD2,""))))),"") -> 1.1841063 | AF2: =IF(AE2="","",IF(AB2="t_paired",1-3/(4*(V2-1)-1),1-3/(4*(V2+Y2)-9))) -> 0.98461538 | AG2: =IF(AE2="","",AE2*AF2) -> 1.1658893 | AH2: =IF(AG2="","",IF(AB2="t_paired",1/V2+AG2^2/(2*V2),(V2+Y2)/(V2*Y2)+AG2^2/(2*(V2+Y2)))) -> 0.091787987 | AI2: =IF(AH2="","",SQRT(AH2)) -> 0.30296532 | AJ2: =IF(AI2="","",AG2-1.96*AI2) -> 0.57207723 | AK2: =IF(AI2="","",AG2+1.96*AI2) -> 1.7597013 | AL2: =IF(AI2="","",AG2/AI2) -> 3.8482598 | AM2: =IF(AL2="","",2*(1-NORMSDIST(ABS(AL2)))) -> 0.00011895988 | AN2: =IF(COUNT(V2)=0,"",IF(AB2="t_paired",V2,V2+N(Y2))) -> 51 | AO2: =IF(AH2="","",1/AH2) -> 10.894672 | AP2: Y | AQ2: Extracted from uploaded paper (replaces rows in your workbook(s): WB2) | AR2: Condition main effect F(1,49)=17.87; d=2*sqrt(F/df) | AS2: =IF(AND(AP2="Y",ISNUMBER(AO2)),AO2,0) -> 10.894672 | AT2: =IF(AS2>0,AS2*AG2,0) -> 12.701981 | AU2: =IF(AS2>0,AS2*AG2^2,0) -> 14.809103 | AV2: =IF(AS2>0,AS2^2,0) -> 118.69387 | AW2: =IF(AS2>0,AG2,0) -> 1.1658893 | AX2: =IF(AS2>0,AH2,1) -> 0.091787987
A3: ES002 | B3: S001 | C3: Abdelghani et al. (2022) | D3: 2022 | E3: France | F3: Primary education | G3: Science / general knowledge (reading-based) | H3: Conversational AI / chatbot | I3: Conversational AI (pedagogical agent) - 'Kids Ask' incentive conversational agent (semantic cues) | J3: No | K3: Pseudo-randomized controlled experiment, 2 groups | L3: Neutral conversational agent (no cues) | M3: 4 sessions in 1 week | N3: 75 per session | O3: Less than 1 week | P3: Cognitive | Q3: Higher-order thinking skills | S3: Quality of questions generated | T3: Question quality grid score | U3: Post-test | V3: 25 | Y3: 26 | AB3: F | AC3: 37.48 | AD3: 1 | AE3: =IFERROR(IF(AB3="MSD",IF(COUNT(V3,W3,X3,Y3,Z3,AA3)<6,"",(W3-Z3)/SQRT(((V3-1)*X3^2+(Y3-1)*AA3^2)/(V3+Y3-2))*AD3),IF(AB3="t",AC3*SQRT(1/V3+1/Y3)*AD3,IF(AB3="F",SQRT(AC3)*SQRT(1/V3+1/Y3)*AD3,IF(AB3="z",2*(AC3/SQRT(V3+Y3))/SQRT(1-(AC3/SQRT(V3+Y3))^2)*AD3,IF(AB3="t_paired",AC3/SQRT(V3)*AD3,""))))),"") -> 1.7148581 | AF3: =IF(AE3="","",IF(AB3="t_paired",1-3/(4*(V3-1)-1),1-3/(4*(V3+Y3)-9))) -> 0.98461538 | AG3: =IF(AE3="","",AE3*AF3) -> 1.6884757 | AH3: =IF(AG3="","",IF(AB3="t_paired",1/V3+AG3^2/(2*V3),(V3+Y3)/(V3*Y3)+AG3^2/(2*(V3+Y3)))) -> 0.10641203 | AI3: =IF(AH3="","",SQRT(AH3)) -> 0.32620857 | AJ3: =IF(AI3="","",AG3-1.96*AI3) -> 1.0491069 | AK3: =IF(AI3="","",AG3+1.96*AI3) -> 2.3278445 | AL3: =IF(AI3="","",AG3/AI3) -> 5.1760618 | AM3: =IF(AL3="","",2*(1-NORMSDIST(ABS(AL3)))) -> 2.2661843e-07 | AN3: =IF(COUNT(V3)=0,"",IF(AB3="t_paired",V3,V3+N(Y3))) -> 51 | AO3: =IF(AH3="","",1/AH3) -> 9.3974336 | AP3: Y | AQ3: Extracted from uploaded paper (replaces rows in your workbook(s): WB2) | AR3: Condition main effect F(1,49)=37.48 | AS3: =IF(AND(AP3="Y",ISNUMBER(AO3)),AO3,0) -> 9.3974336 | AT3: =IF(AS3>0,AS3*AG3,0) -> 15.867338 | AU3: =IF(AS3>0,AS3*AG3^2,0) -> 26.791616 | AV3: =IF(AS3>0,AS3^2,0) -> 88.311759 | AW3: =IF(AS3>0,AG3,0) -> 1.6884757 | AX3: =IF(AS3>0,AH3,1) -> 0.10641203
A4: ES003 | B4: S001 | C4: Abdelghani et al. (2022) | D4: 2022 | E4: France | F4: Primary education | G4: Science / general knowledge (reading-based) | H4: Conversational AI / chatbot | I4: Conversational AI (pedagogical agent) - 'Kids Ask' incentive conversational agent (semantic cues) | J4: No | K4: Pseudo-randomized controlled experiment, 2 groups | L4: Neutral conversational agent (no cues) | M4: 4 sessions in 1 week | N4: 75 per session | O4: Less than 1 week | P4: Cognitive | Q4: Higher-order thinking skills | S4: Question-asking (QA) fluency | T4: Offline divergent QA fluency test (2 min) | U4: Pre-test | V4: 25 | W4: 8.24 | X4: 5.56 | Y4: 26 | Z4: 9.61 | AA4: 7.38 | AB4: MSD | AD4: 1 | AE4: =IFERROR(IF(AB4="MSD",IF(COUNT(V4,W4,X4,Y4,Z4,AA4)<6,"",(W4-Z4)/SQRT(((V4-1)*X4^2+(Y4-1)*AA4^2)/(V4+Y4-2))*AD4),IF(AB4="t",AC4*SQRT(1/V4+1/Y4)*AD4,IF(AB4="F",SQRT(AC4)*SQRT(1/V4+1/Y4)*AD4,IF(AB4="z",2*(AC4/SQRT(V4+Y4))/SQRT(1-(AC4/SQRT(V4+Y4))^2)*AD4,IF(AB4="t_paired",AC4/SQRT(V4)*AD4,""))))),"") -> -0.20909497 | AF4: =IF(AE4="","",IF(AB4="t_paired",1-3/(4*(V4-1)-1),1-3/(4*(V4+Y4)-9))) -> 0.98461538 | AG4: =IF(AE4="","",AE4*AF4) -> -0.20587813 | AH4: =IF(AG4="","",IF(AB4="t_paired",1/V4+AG4^2/(2*V4),(V4+Y4)/(V4*Y4)+AG4^2/(2*(V4+Y4)))) -> 0.078877086 | AI4: =IF(AH4="","",SQRT(AH4)) -> 0.28085065 | AJ4: =IF(AI4="","",AG4-1.96*AI4) -> -0.75634539 | AK4: =IF(AI4="","",AG4+1.96*AI4) -> 0.34458914 | AL4: =IF(AI4="","",AG4/AI4) -> -0.733052 | AM4: =IF(AL4="","",2*(1-NORMSDIST(ABS(AL4)))) -> 0.46352672 | AN4: =IF(COUNT(V4)=0,"",IF(AB4="t_paired",V4,V4+N(Y4))) -> 51 | AO4: =IF(AH4="","",1/AH4) -> 12.677953 | AP4: N | AQ4: Extracted from uploaded paper (replaces rows in your workbook(s): WB2) | AR4: Table 2 baseline | AS4: =IF(AND(AP4="Y",ISNUMBER(AO4)),AO4,0) -> 0 | AT4: =IF(AS4>0,AS4*AG4,0) -> 0 | AU4: =IF(AS4>0,AS4*AG4^2,0) -> 0 | AV4: =IF(AS4>0,AS4^2,0) -> 0 | AW4: =IF(AS4>0,AG4,0) -> 0 | AX4: =IF(AS4>0,AH4,1) -> 1
A5: ES004 | B5: S001 | C5: Abdelghani et al. (2022) | D5: 2022 | E5: France | F5: Primary education | G5: Science / general knowledge (reading-based) | H5: Conversational AI / chatbot | I5: Conversational AI (pedagogical agent) - 'Kids Ask' incentive conversational agent (semantic cues) | J5: No | K5: Pseudo-randomized controlled experiment, 2 groups | L5: Neutral conversational agent (no cues) | M5: 4 sessions in 1 week | N5: 75 per session | O5: Less than 1 week | P5: Cognitive | Q5: Knowledge-based outcome | S5: Domain-knowledge quiz | T5: Domain-knowledge quiz (max 9) | U5: Pre-test | V5: 25 | W5: 2.32 | X5: 2.91 | Y5: 26 | Z5: 2.73 | AA5: 2.34 | AB5: MSD | AD5: 1 | AE5: =IFERROR(IF(AB5="MSD",IF(COUNT(V5,W5,X5,Y5,Z5,AA5)<6,"",(W5-Z5)/SQRT(((V5-1)*X5^2+(Y5-1)*AA5^2)/(V5+Y5-2))*AD5),IF(AB5="t",AC5*SQRT(1/V5+1/Y5)*AD5,IF(AB5="F",SQRT(AC5)*SQRT(1/V5+1/Y5)*AD5,IF(AB5="z",2*(AC5/SQRT(V5+Y5))/SQRT(1-(AC5/SQRT(V5+Y5))^2)*AD5,IF(AB5="t_paired",AC5/SQRT(V5)*AD5,""))))),"") -> -0.15561914 | AF5: =IF(AE5="","",IF(AB5="t_paired",1-3/(4*(V5-1)-1),1-3/(4*(V5+Y5)-9))) -> 0.98461538 | AG5: =IF(AE5="","",AE5*AF5) -> -0.153225 | AH5: =IF(AG5="","",IF(AB5="t_paired",1/V5+AG5^2/(2*V5),(V5+Y5)/(V5*Y5)+AG5^2/(2*(V5+Y5)))) -> 0.078691714 | AI5: =IF(AH5="","",SQRT(AH5)) -> 0.28052043 | AJ5: =IF(AI5="","",AG5-1.96*AI5) -> -0.70304505 | AK5: =IF(AI5="","",AG5+1.96*AI5) -> 0.39659505 | AL5: =IF(AI5="","",AG5/AI5) -> -0.54621688 | AM5: =IF(AL5="","",2*(1-NORMSDIST(ABS(AL5)))) -> 0.58491686 | AN5: =IF(COUNT(V5)=0,"",IF(AB5="t_paired",V5,V5+N(Y5))) -> 51 | AO5: =IF(AH5="","",1/AH5) -> 12.707818 | AP5: N | AQ5: Extracted from uploaded paper (replaces rows in your workbook(s): WB2) | AR5: Sec 5.2 | AS5: =IF(AND(AP5="Y",ISNUMBER(AO5)),AO5,0) -> 0 | AT5: =IF(AS5>0,AS5*AG5,0) -> 0 | AU5: =IF(AS5>0,AS5*AG5^2,0) -> 0 | AV5: =IF(AS5>0,AS5^2,0) -> 0 | AW5: =IF(AS5>0,AG5,0) -> 0 | AX5: =IF(AS5>0,AH5,1) -> 1
A6: ES005 | B6: S001 | C6: Abdelghani et al. (2022) | D6: 2022 | E6: France | F6: Primary education | G6: Science / general knowledge (reading-based) | H6: Conversational AI / chatbot | I6: Conversational AI (pedagogical agent) - 'Kids Ask' incentive conversational agent (semantic cues) | J6: No | K6: Pseudo-randomized controlled experiment, 2 groups | L6: Neutral conversational agent (no cues) | M6: 4 sessions in 1 week | N6: 75 per session | O6: Less than 1 week | P6: Cognitive | Q6: Knowledge-based outcome | S6: Learning progress (knowledge gain) | T6: Domain-knowledge quiz progress score | U6: Gain (post-pre) | V6: 25 | W6: 0.25 | X6: 0.41 | Y6: 26 | Z6: -0.009 | AA6: 0.45 | AB6: MSD | AD6: 1 | AE6: =IFERROR(IF(AB6="MSD",IF(COUNT(V6,W6,X6,Y6,Z6,AA6)<6,"",(W6-Z6)/SQRT(((V6-1)*X6^2+(Y6-1)*AA6^2)/(V6+Y6-2))*AD6),IF(AB6="t",AC6*SQRT(1/V6+1/Y6)*AD6,IF(AB6="F",SQRT(AC6)*SQRT(1/V6+1/Y6)*AD6,IF(AB6="z",2*(AC6/SQRT(V6+Y6))/SQRT(1-(AC6/SQRT(V6+Y6))^2)*AD6,IF(AB6="t_paired",AC6/SQRT(V6)*AD6,""))))),"") -> 0.60110604 | AF6: =IF(AE6="","",IF(AB6="t_paired",1-3/(4*(V6-1)-1),1-3/(4*(V6+Y6)-9))) -> 0.98461538 | AG6: =IF(AE6="","",AE6*AF6) -> 0.59185826 | AH6: =IF(AG6="","",IF(AB6="t_paired",1/V6+AG6^2/(2*V6),(V6+Y6)/(V6*Y6)+AG6^2/(2*(V6+Y6)))) -> 0.081895815 | AI6: =IF(AH6="","",SQRT(AH6)) -> 0.28617445 | AJ6: =IF(AI6="","",AG6-1.96*AI6) -> 0.030956339 | AK6: =IF(AI6="","",AG6+1.96*AI6) -> 1.1527602 | AL6: =IF(AI6="","",AG6/AI6) -> 2.068173 | AM6: =IF(AL6="","",2*(1-NORMSDIST(ABS(AL6)))) -> 0.038623761 | AN6: =IF(COUNT(V6)=0,"",IF(AB6="t_paired",V6,V6+N(Y6))) -> 51 | AO6: =IF(AH6="","",1/AH6) -> 12.210636 | AP6: Y | AQ6: Extracted from uploaded paper (replaces rows in your workbook(s): WB2) | AR6: Sec 5.2, p=.04 | AS6: =IF(AND(AP6="Y",ISNUMBER(AO6)),AO6,0) -> 12.210636 | AT6: =IF(AS6>0,AS6*AG6,0) -> 7.2269658 | AU6: =IF(AS6>0,AS6*AG6^2,0) -> 4.2773394 | AV6: =IF(AS6>0,AS6^2,0) -> 149.09964 | AW6: =IF(AS6>0,AG6,0) -> 0.59185826 | AX6: =IF(AS6>0,AH6,1) -> 0.081895815
A7: ES006 | B7: S001 | C7: Abdelghani et al. (2022) | D7: 2022 | E7: France | F7: Primary education | G7: Science / general knowledge (reading-based) | H7: Conversational AI / chatbot | I7: Conversational AI (pedagogical agent) - 'Kids Ask' incentive conversational agent (semantic cues) | J7: No | K7: Pseudo-randomized controlled experiment, 2 groups | L7: Neutral conversational agent (no cues) | M7: 4 sessions in 1 week | N7: 75 per session | O7: Less than 1 week | P7: Non-cognitive | Q7: Curiosity | R7: Trait curiosity | S7: Curiosity trait | T7: Curiosity trait questionnaire (profile measure) | U7: Pre-test | V7: 25 | W7: 27.12 | X7: 4.8 | Y7: 26 | Z7: 29.3 | AA7: 4.3 | AB7: MSD | AD7: 1 | AE7: =IFERROR(IF(AB7="MSD",IF(COUNT(V7,W7,X7,Y7,Z7,AA7)<6,"",(W7-Z7)/SQRT(((V7-1)*X7^2+(Y7-1)*AA7^2)/(V7+Y7-2))*AD7),IF(AB7="t",AC7*SQRT(1/V7+1/Y7)*AD7,IF(AB7="F",SQRT(AC7)*SQRT(1/V7+1/Y7)*AD7,IF(AB7="z",2*(AC7/SQRT(V7+Y7))/SQRT(1-(AC7/SQRT(V7+Y7))^2)*AD7,IF(AB7="t_paired",AC7/SQRT(V7)*AD7,""))))),"") -> -0.47893502 | AF7: =IF(AE7="","",IF(AB7="t_paired",1-3/(4*(V7-1)-1),1-3/(4*(V7+Y7)-9))) -> 0.98461538 | AG7: =IF(AE7="","",AE7*AF7) -> -0.47156678 | AH7: =IF(AG7="","",IF(AB7="t_paired",1/V7+AG7^2/(2*V7),(V7+Y7)/(V7*Y7)+AG7^2/(2*(V7+Y7)))) -> 0.080641688 | AI7: =IF(AH7="","",SQRT(AH7)) -> 0.2839748 | AJ7: =IF(AI7="","",AG7-1.96*AI7) -> -1.0281574 | AK7: =IF(AI7="","",AG7+1.96*AI7) -> 0.085023826 | AL7: =IF(AI7="","",AG7/AI7) -> -1.6605938 | AM7: =IF(AL7="","",2*(1-NORMSDIST(ABS(AL7)))) -> 0.096795062 | AN7: =IF(COUNT(V7)=0,"",IF(AB7="t_paired",V7,V7+N(Y7))) -> 51 | AO7: =IF(AH7="","",1/AH7) -> 12.400534 | AP7: N | AQ7: Extracted from uploaded paper (replaces rows in your workbook(s): WB2) | AR7: Table 2 baseline profile. NB: your curiosity workbook entered this as Post-test | AS7: =IF(AND(AP7="Y",ISNUMBER(AO7)),AO7,0) -> 0 | AT7: =IF(AS7>0,AS7*AG7,0) -> 0 | AU7: =IF(AS7>0,AS7*AG7^2,0) -> 0 | AV7: =IF(AS7>0,AS7^2,0) -> 0 | AW7: =IF(AS7>0,AG7,0) -> 0 | AX7: =IF(AS7>0,AH7,1) -> 1
A8: ES007 | B8: S001 | C8: Abdelghani et al. (2022) | D8: 2022 | E8: France | F8: Primary education | G8: Science / general knowledge (reading-based) | H8: Conversational AI / chatbot | I8: Conversational AI (pedagogical agent) - 'Kids Ask' incentive conversational agent (semantic cues) | J8: No | K8: Pseudo-randomized controlled experiment, 2 groups | L8: Neutral conversational agent (no cues) | M8: 4 sessions in 1 week | N8: 75 per session | O8: Less than 1 week | P8: Non-cognitive | Q8: Curiosity | R8: Perceptual curiosity | S8: Exploration time (curiosity-driven exploration) | T8: Time spent exploring resources (s) | U8: Post-test | V8: 25 | W8: 1593.15 | X8: 634.81 | Y8: 26 | Z8: 1222.95 | AA8: 439.76 | AB8: MSD | AD8: 1 | AE8: =IFERROR(IF(AB8="MSD",IF(COUNT(V8,W8,X8,Y8,Z8,AA8)<6,"",(W8-Z8)/SQRT(((V8-1)*X8^2+(Y8-1)*AA8^2)/(V8+Y8-2))*AD8),IF(AB8="t",AC8*SQRT(1/V8+1/Y8)*AD8,IF(AB8="F",SQRT(AC8)*SQRT(1/V8+1/Y8)*AD8,IF(AB8="z",2*(AC8/SQRT(V8+Y8))/SQRT(1-(AC8/SQRT(V8+Y8))^2)*AD8,IF(AB8="t_paired",AC8/SQRT(V8)*AD8,""))))),"") -> 0.68038646 | AF8: =IF(AE8="","",IF(AB8="t_paired",1-3/(4*(V8-1)-1),1-3/(4*(V8+Y8)-9))) -> 0.98461538 | AG8: =IF(AE8="","",AE8*AF8) -> 0.66991897 | AH8: =IF(AG8="","",IF(AB8="t_paired",1/V8+AG8^2/(2*V8),(V8+Y8)/(V8*Y8)+AG8^2/(2*(V8+Y8)))) -> 0.082861454 | AI8: =IF(AH8="","",SQRT(AH8)) -> 0.28785666 | AJ8: =IF(AI8="","",AG8-1.96*AI8) -> 0.10571993 | AK8: =IF(AI8="","",AG8+1.96*AI8) -> 1.234118 | AL8: =IF(AI8="","",AG8/AI8) -> 2.3272659 | AM8: =IF(AL8="","",2*(1-NORMSDIST(ABS(AL8)))) -> 0.019951118 | AN8: =IF(COUNT(V8)=0,"",IF(AB8="t_paired",V8,V8+N(Y8))) -> 51 | AO8: =IF(AH8="","",1/AH8) -> 12.068338 | AP8: Y | AQ8: Extracted from uploaded paper (replaces rows in your workbook(s): WB2) | AR8: Sec 5.1.2, reported d=0.68 | AS8: =IF(AND(AP8="Y",ISNUMBER(AO8)),AO8,0) -> 12.068338 | AT8: =IF(AS8>0,AS8*AG8,0) -> 8.0848083 | AU8: =IF(AS8>0,AS8*AG8^2,0) -> 5.4161665 | AV8: =IF(AS8>0,AS8^2,0) -> 145.64477 | AW8: =IF(AS8>0,AG8,0) -> 0.66991897 | AX8: =IF(AS8>0,AH8,1) -> 0.082861454
A9: ES008 | B9: S001 | C9: Abdelghani et al. (2022) | D9: 2022 | E9: France | F9: Primary education | G9: Science / general knowledge (reading-based) | H9: Conversational AI / chatbot | I9: Conversational AI (pedagogical agent) - 'Kids Ask' incentive conversational agent (semantic cues) | J9: No | K9: Pseudo-randomized controlled experiment, 2 groups | L9: Neutral conversational agent (no cues) | M9: 4 sessions in 1 week | N9: 75 per session | O9: Less than 1 week | P9: Non-cognitive | Q9: Curiosity | R9: Epistemic curiosity | S9: Perception of curiosity | T9: CIAC perception of curiosity questionnaire | U9: Pre-test | V9: 25 | W9: 37.5 | X9: 6.58 | Y9: 26 | Z9: 38.8 | AA9: 8 | AB9: MSD | AD9: 1 | AE9: =IFERROR(IF(AB9="MSD",IF(COUNT(V9,W9,X9,Y9,Z9,AA9)<6,"",(W9-Z9)/SQRT(((V9-1)*X9^2+(Y9-1)*AA9^2)/(V9+Y9-2))*AD9),IF(AB9="t",AC9*SQRT(1/V9+1/Y9)*AD9,IF(AB9="F",SQRT(AC9)*SQRT(1/V9+1/Y9)*AD9,IF(AB9="z",2*(AC9/SQRT(V9+Y9))/SQRT(1-(AC9/SQRT(V9+Y9))^2)*AD9,IF(AB9="t_paired",AC9/SQRT(V9)*AD9,""))))),"") -> -0.17713825 | AF9: =IF(AE9="","",IF(AB9="t_paired",1-3/(4*(V9-1)-1),1-3/(4*(V9+Y9)-9))) -> 0.98461538 | AG9: =IF(AE9="","",AE9*AF9) -> -0.17441305 | AH9: =IF(AG9="","",IF(AB9="t_paired",1/V9+AG9^2/(2*V9),(V9+Y9)/(V9*Y9)+AG9^2/(2*(V9+Y9)))) -> 0.078759773 | AI9: =IF(AH9="","",SQRT(AH9)) -> 0.28064172 | AJ9: =IF(AI9="","",AG9-1.96*AI9) -> -0.72447081 | AK9: =IF(AI9="","",AG9+1.96*AI9) -> 0.37564472 | AL9: =IF(AI9="","",AG9/AI9) -> -0.6214794 | AM9: =IF(AL9="","",2*(1-NORMSDIST(ABS(AL9)))) -> 0.53428424 | AN9: =IF(COUNT(V9)=0,"",IF(AB9="t_paired",V9,V9+N(Y9))) -> 51 | AO9: =IF(AH9="","",1/AH9) -> 12.696837 | AP9: N | AQ9: Extracted from uploaded paper (replaces rows in your workbook(s): WB2) | AR9: Table 2 baseline profile. NB: your curiosity workbook entered this as Post-test | AS9: =IF(AND(AP9="Y",ISNUMBER(AO9)),AO9,0) -> 0 | AT9: =IF(AS9>0,AS9*AG9,0) -> 0 | AU9: =IF(AS9>0,AS9*AG9^2,0) -> 0 | AV9: =IF(AS9>0,AS9^2,0) -> 0 | AW9: =IF(AS9>0,AG9,0) -> 0 | AX9: =IF(AS9>0,AH9,1) -> 1
A10: ES009 | B10: S002 | C10: Abdelghani et al. (2024) | D10: 2024 | E10: France | F10: Primary education | G10: Science / general knowledge (reading-based) | H10: Generative AI (LLM-based) | I10: Generative AI (LLM pedagogical agent) - GPT-3-driven 'open' conversational agent (Kids Ask) | J10: No | K10: Pseudo-randomized experiment, 3 groups (active comparator) | L10: Hand-crafted incentive conversational agent (non-generative cues) - active comparator | M10: 3 sessions in 1 week | N10: 60 per session | O10: Less than 1 week | P10: Cognitive | Q10: Higher-order thinking skills | S10: Percentage of divergent questions generated | T10: Divergent QA % during training | U10: Post-test | V10: 25 | Y10: 24 | AB10: t | AC10: 3.17 | AD10: 1 | AE10: =IFERROR(IF(AB10="MSD",IF(COUNT(V10,W10,X10,Y10,Z10,AA10)<6,"",(W10-Z10)/SQRT(((V10-1)*X10^2+(Y10-1)*AA10^2)/(V10+Y10-2))*AD10),IF(AB10="t",AC10*SQRT(1/V10+1/Y10)*AD10,IF(AB10="F",SQRT(AC10)*SQRT(1/V10+1/Y10)*AD10,IF(AB10="z",2*(AC10/SQRT(V10+Y10))/SQRT(1-(AC10/SQRT(V10+Y10))^2)*AD10,IF(AB10="t_paired",AC10/SQRT(V10)*AD10,""))))),"") -> 0.90590296 | AF10: =IF(AE10="","",IF(AB10="t_paired",1-3/(4*(V10-1)-1),1-3/(4*(V10+Y10)-9))) -> 0.98395722 | AG10: =IF(AE10="","",AE10*AF10) -> 0.89136975 | AH10: =IF(AG10="","",IF(AB10="t_paired",1/V10+AG10^2/(2*V10),(V10+Y10)/(V10*Y10)+AG10^2/(2*(V10+Y10)))) -> 0.089774218 | AI10: =IF(AH10="","",SQRT(AH10)) -> 0.29962346 | AJ10: =IF(AI10="","",AG10-1.96*AI10) -> 0.30410777 | AK10: =IF(AI10="","",AG10+1.96*AI10) -> 1.4786317 | AL10: =IF(AI10="","",AG10/AI10) -> 2.9749665 | AM10: =IF(AL10="","",2*(1-NORMSDIST(ABS(AL10)))) -> 0.0029302056 | AN10: =IF(COUNT(V10)=0,"",IF(AB10="t_paired",V10,V10+N(Y10))) -> 49 | AO10: =IF(AH10="","",1/AH10) -> 11.139056 | AP10: Y | AQ10: Extracted from uploaded paper (replaces rows in your workbook(s): WB2) | AR10: GPT-3 open vs hand-crafted: t=-3.17 (open higher), p=.003 | AS10: =IF(AND(AP10="Y",ISNUMBER(AO10)),AO10,0) -> 11.139056 | AT10: =IF(AS10>0,AS10*AG10,0) -> 9.9290172 | AU10: =IF(AS10>0,AS10*AG10^2,0) -> 8.8504256 | AV10: =IF(AS10>0,AS10^2,0) -> 124.07856 | AW10: =IF(AS10>0,AG10,0) -> 0.89136975 | AX10: =IF(AS10>0,AH10,1) -> 0.089774218
A11: ES010 | B11: S002 | C11: Abdelghani et al. (2024) | D11: 2024 | E11: France | F11: Primary education | G11: Science / general knowledge (reading-based) | H11: Generative AI (LLM-based) | I11: Generative AI (LLM pedagogical agent) - GPT-3-driven 'open' conversational agent (Kids Ask) | J11: No | K11: Pseudo-randomized experiment, 3 groups (active comparator) | L11: Hand-crafted incentive conversational agent (non-generative cues) - active comparator | M11: 3 sessions in 1 week | N11: 60 per session | O11: Less than 1 week | P11: Cognitive | Q11: Higher-order thinking skills | S11: Quality of questions generated | T11: Question quality grid score | U11: Post-test | V11: 25 | Y11: 24 | AB11: t | AC11: 0.29 | AD11: 1 | AE11: =IFERROR(IF(AB11="MSD",IF(COUNT(V11,W11,X11,Y11,Z11,AA11)<6,"",(W11-Z11)/SQRT(((V11-1)*X11^2+(Y11-1)*AA11^2)/(V11+Y11-2))*AD11),IF(AB11="t",AC11*SQRT(1/V11+1/Y11)*AD11,IF(AB11="F",SQRT(AC11)*SQRT(1/V11+1/Y11)*AD11,IF(AB11="z",2*(AC11/SQRT(V11+Y11))/SQRT(1-(AC11/SQRT(V11+Y11))^2)*AD11,IF(AB11="t_paired",AC11/SQRT(V11)*AD11,""))))),"") -> 0.082874403 | AF11: =IF(AE11="","",IF(AB11="t_paired",1-3/(4*(V11-1)-1),1-3/(4*(V11+Y11)-9))) -> 0.98395722 | AG11: =IF(AE11="","",AE11*AF11) -> 0.081544867 | AH11: =IF(AG11="","",IF(AB11="t_paired",1/V11+AG11^2/(2*V11),(V11+Y11)/(V11*Y11)+AG11^2/(2*(V11+Y11)))) -> 0.081734519 | AI11: =IF(AH11="","",SQRT(AH11)) -> 0.2858925 | AJ11: =IF(AI11="","",AG11-1.96*AI11) -> -0.47880443 | AK11: =IF(AI11="","",AG11+1.96*AI11) -> 0.64189416 | AL11: =IF(AI11="","",AG11/AI11) -> 0.28522913 | AM11: =IF(AL11="","",2*(1-NORMSDIST(ABS(AL11)))) -> 0.77546861 | AN11: =IF(COUNT(V11)=0,"",IF(AB11="t_paired",V11,V11+N(Y11))) -> 49 | AO11: =IF(AH11="","",1/AH11) -> 12.234733 | AP11: Y | AQ11: Extracted from uploaded paper (replaces rows in your workbook(s): WB2) | AR11: GPT-3 open vs hand-crafted t=-0.29 (n.s.); direction from figure | AS11: =IF(AND(AP11="Y",ISNUMBER(AO11)),AO11,0) -> 12.234733 | AT11: =IF(AS11>0,AS11*AG11,0) -> 0.99767965 | AU11: =IF(AS11>0,AS11*AG11^2,0) -> 0.081355655 | AV11: =IF(AS11>0,AS11^2,0) -> 149.68869 | AW11: =IF(AS11>0,AG11,0) -> 0.081544867 | AX11: =IF(AS11>0,AH11,1) -> 0.081734519
A12: ES011 | B12: S002 | C12: Abdelghani et al. (2024) | D12: 2024 | E12: France | F12: Primary education | G12: Science / general knowledge (reading-based) | H12: Generative AI (LLM-based) | I12: Generative AI (LLM pedagogical agent) - GPT-3-driven 'open' conversational agent (Kids Ask) | J12: No | K12: Pseudo-randomized experiment, 3 groups (active comparator) | L12: Hand-crafted incentive conversational agent (non-generative cues) - active comparator | M12: 3 sessions in 1 week | N12: 60 per session | O12: Less than 1 week | P12: Cognitive | Q12: Higher-order thinking skills | S12: Use of agent cues (%) | T12: % questions using agent cues | U12: Post-test | V12: 25 | W12: 91.78 | X12: 8.83 | Y12: 24 | Z12: 77.28 | AA12: 23.08 | AB12: MSD | AD12: 1 | AE12: =IFERROR(IF(AB12="MSD",IF(COUNT(V12,W12,X12,Y12,Z12,AA12)<6,"",(W12-Z12)/SQRT(((V12-1)*X12^2+(Y12-1)*AA12^2)/(V12+Y12-2))*AD12),IF(AB12="t",AC12*SQRT(1/V12+1/Y12)*AD12,IF(AB12="F",SQRT(AC12)*SQRT(1/V12+1/Y12)*AD12,IF(AB12="z",2*(AC12/SQRT(V12+Y12))/SQRT(1-(AC12/SQRT(V12+Y12))^2)*AD12,IF(AB12="t_paired",AC12/SQRT(V12)*AD12,""))))),"") -> 0.83647473 | AF12: =IF(AE12="","",IF(AB12="t_paired",1-3/(4*(V12-1)-1),1-3/(4*(V12+Y12)-9))) -> 0.98395722 | AG12: =IF(AE12="","",AE12*AF12) -> 0.82305535 | AH12: =IF(AG12="","",IF(AB12="t_paired",1/V12+AG12^2/(2*V12),(V12+Y12)/(V12*Y12)+AG12^2/(2*(V12+Y12)))) -> 0.088579117 | AI12: =IF(AH12="","",SQRT(AH12)) -> 0.29762244 | AJ12: =IF(AI12="","",AG12-1.96*AI12) -> 0.23971537 | AK12: =IF(AI12="","",AG12+1.96*AI12) -> 1.4063953 | AL12: =IF(AI12="","",AG12/AI12) -> 2.7654344 | AM12: =IF(AL12="","",2*(1-NORMSDIST(ABS(AL12)))) -> 0.005684703 | AN12: =IF(COUNT(V12)=0,"",IF(AB12="t_paired",V12,V12+N(Y12))) -> 49 | AO12: =IF(AH12="","",1/AH12) -> 11.289343 | AP12: Y | AQ12: Extracted from uploaded paper (replaces rows in your workbook(s): WB2) | AR12: Sec 8.2.1 | AS12: =IF(AND(AP12="Y",ISNUMBER(AO12)),AO12,0) -> 11.289343 | AT12: =IF(AS12>0,AS12*AG12,0) -> 9.2917538 | AU12: =IF(AS12>0,AS12*AG12^2,0) -> 7.6476277 | AV12: =IF(AS12>0,AS12^2,0) -> 127.44926 | AW12: =IF(AS12>0,AG12,0) -> 0.82305535 | AX12: =IF(AS12>0,AH12,1) -> 0.088579117
A13: ES012 | B13: S002 | C13: Abdelghani et al. (2024) | D13: 2024 | E13: France | F13: Primary education | G13: Science / general knowledge (reading-based) | H13: Generative AI (LLM-based) | I13: Generative AI (LLM pedagogical agent) - GPT-3-driven 'open' conversational agent (Kids Ask) | J13: No | K13: Pseudo-randomized experiment, 3 groups (active comparator) | L13: Hand-crafted incentive conversational agent (non-generative cues) - active comparator | M13: 3 sessions in 1 week | N13: 60 per session | O13: Less than 1 week | P13: Cognitive | Q13: Knowledge-based outcome | S13: Domain-knowledge quiz | T13: Domain-knowledge quiz (profile) | U13: Pre-test | V13: 25 | W13: 8.72 | X13: 4.05 | Y13: 24 | Z13: 6.9 | AA13: 4.6 | AB13: MSD | AD13: 1 | AE13: =IFERROR(IF(AB13="MSD",IF(COUNT(V13,W13,X13,Y13,Z13,AA13)<6,"",(W13-Z13)/SQRT(((V13-1)*X13^2+(Y13-1)*AA13^2)/(V13+Y13-2))*AD13),IF(AB13="t",AC13*SQRT(1/V13+1/Y13)*AD13,IF(AB13="F",SQRT(AC13)*SQRT(1/V13+1/Y13)*AD13,IF(AB13="z",2*(AC13/SQRT(V13+Y13))/SQRT(1-(AC13/SQRT(V13+Y13))^2)*AD13,IF(AB13="t_paired",AC13/SQRT(V13)*AD13,""))))),"") -> 0.42052818 | AF13: =IF(AE13="","",IF(AB13="t_paired",1-3/(4*(V13-1)-1),1-3/(4*(V13+Y13)-9))) -> 0.98395722 | AG13: =IF(AE13="","",AE13*AF13) -> 0.41378173 | AH13: =IF(AG13="","",IF(AB13="t_paired",1/V13+AG13^2/(2*V13),(V13+Y13)/(V13*Y13)+AG13^2/(2*(V13+Y13)))) -> 0.083413762 | AI13: =IF(AH13="","",SQRT(AH13)) -> 0.28881441 | AJ13: =IF(AI13="","",AG13-1.96*AI13) -> -0.1522945 | AK13: =IF(AI13="","",AG13+1.96*AI13) -> 0.97985797 | AL13: =IF(AI13="","",AG13/AI13) -> 1.4326908 | AM13: =IF(AL13="","",2*(1-NORMSDIST(ABS(AL13)))) -> 0.15194623 | AN13: =IF(COUNT(V13)=0,"",IF(AB13="t_paired",V13,V13+N(Y13))) -> 49 | AO13: =IF(AH13="","",1/AH13) -> 11.988429 | AP13: N | AQ13: Extracted from uploaded paper (replaces rows in your workbook(s): WB2) | AR13: Table 1 baseline | AS13: =IF(AND(AP13="Y",ISNUMBER(AO13)),AO13,0) -> 0 | AT13: =IF(AS13>0,AS13*AG13,0) -> 0 | AU13: =IF(AS13>0,AS13*AG13^2,0) -> 0 | AV13: =IF(AS13>0,AS13^2,0) -> 0 | AW13: =IF(AS13>0,AG13,0) -> 0 | AX13: =IF(AS13>0,AH13,1) -> 1
A14: ES013 | B14: S002 | C14: Abdelghani et al. (2024) | D14: 2024 | E14: France | F14: Primary education | G14: Science / general knowledge (reading-based) | H14: Generative AI (LLM-based) | I14: Generative AI (LLM pedagogical agent) - GPT-3-driven 'open' conversational agent (Kids Ask) | J14: No | K14: Pseudo-randomized experiment, 3 groups (active comparator) | L14: Hand-crafted incentive conversational agent (non-generative cues) - active comparator | M14: 3 sessions in 1 week | N14: 60 per session | O14: Less than 1 week | P14: Non-cognitive | Q14: Curiosity | R14: Trait curiosity | S14: Curiosity trait | T14: Curiosity trait questionnaire (profile) | U14: Pre-test | V14: 25 | W14: 28.36 | X14: 4.75 | Y14: 24 | Z14: 27.2 | AA14: 4.38 | AB14: MSD | AD14: 1 | AE14: =IFERROR(IF(AB14="MSD",IF(COUNT(V14,W14,X14,Y14,Z14,AA14)<6,"",(W14-Z14)/SQRT(((V14-1)*X14^2+(Y14-1)*AA14^2)/(V14+Y14-2))*AD14),IF(AB14="t",AC14*SQRT(1/V14+1/Y14)*AD14,IF(AB14="F",SQRT(AC14)*SQRT(1/V14+1/Y14)*AD14,IF(AB14="z",2*(AC14/SQRT(V14+Y14))/SQRT(1-(AC14/SQRT(V14+Y14))^2)*AD14,IF(AB14="t_paired",AC14/SQRT(V14)*AD14,""))))),"") -> 0.25368065 | AF14: =IF(AE14="","",IF(AB14="t_paired",1-3/(4*(V14-1)-1),1-3/(4*(V14+Y14)-9))) -> 0.98395722 | AG14: =IF(AE14="","",AE14*AF14) -> 0.2496109 | AH14: =IF(AG14="","",IF(AB14="t_paired",1/V14+AG14^2/(2*V14),(V14+Y14)/(V14*Y14)+AG14^2/(2*(V14+Y14)))) -> 0.082302438 | AI14: =IF(AH14="","",SQRT(AH14)) -> 0.28688402 | AJ14: =IF(AI14="","",AG14-1.96*AI14) -> -0.31268177 | AK14: =IF(AI14="","",AG14+1.96*AI14) -> 0.81190357 | AL14: =IF(AI14="","",AG14/AI14) -> 0.87007603 | AM14: =IF(AL14="","",2*(1-NORMSDIST(ABS(AL14)))) -> 0.38425886 | AN14: =IF(COUNT(V14)=0,"",IF(AB14="t_paired",V14,V14+N(Y14))) -> 49 | AO14: =IF(AH14="","",1/AH14) -> 12.150308 | AP14: N | AQ14: Extracted from uploaded paper (replaces rows in your workbook(s): WB2) | AR14: Table 1 baseline: Group 3 (GPT-3 open) vs Group 1 (hand-crafted) | AS14: =IF(AND(AP14="Y",ISNUMBER(AO14)),AO14,0) -> 0 | AT14: =IF(AS14>0,AS14*AG14,0) -> 0 | AU14: =IF(AS14>0,AS14*AG14^2,0) -> 0 | AV14: =IF(AS14>0,AS14^2,0) -> 0 | AW14: =IF(AS14>0,AG14,0) -> 0 | AX14: =IF(AS14>0,AH14,1) -> 1
A15: ES014 | B15: S002 | C15: Abdelghani et al. (2024) | D15: 2024 | E15: France | F15: Primary education | G15: Science / general knowledge (reading-based) | H15: Generative AI (LLM-based) | I15: Generative AI (LLM pedagogical agent) - GPT-3-driven 'open' conversational agent (Kids Ask) | J15: No | K15: Pseudo-randomized experiment, 3 groups (active comparator) | L15: Hand-crafted incentive conversational agent (non-generative cues) - active comparator | M15: 3 sessions in 1 week | N15: 60 per session | O15: Less than 1 week | P15: Non-cognitive | Q15: Curiosity | R15: Epistemic curiosity | S15: Perception of curiosity | T15: CIAC perception of curiosity (profile) | U15: Pre-test | V15: 25 | W15: 33.92 | X15: 9.12 | Y15: 24 | Z15: 37.54 | AA15: 6.72 | AB15: MSD | AD15: 1 | AE15: =IFERROR(IF(AB15="MSD",IF(COUNT(V15,W15,X15,Y15,Z15,AA15)<6,"",(W15-Z15)/SQRT(((V15-1)*X15^2+(Y15-1)*AA15^2)/(V15+Y15-2))*AD15),IF(AB15="t",AC15*SQRT(1/V15+1/Y15)*AD15,IF(AB15="F",SQRT(AC15)*SQRT(1/V15+1/Y15)*AD15,IF(AB15="z",2*(AC15/SQRT(V15+Y15))/SQRT(1-(AC15/SQRT(V15+Y15))^2)*AD15,IF(AB15="t_paired",AC15/SQRT(V15)*AD15,""))))),"") -> -0.45049544 | AF15: =IF(AE15="","",IF(AB15="t_paired",1-3/(4*(V15-1)-1),1-3/(4*(V15+Y15)-9))) -> 0.98395722 | AG15: =IF(AE15="","",AE15*AF15) -> -0.44326824 | AH15: =IF(AG15="","",IF(AB15="t_paired",1/V15+AG15^2/(2*V15),(V15+Y15)/(V15*Y15)+AG15^2/(2*(V15+Y15)))) -> 0.083671633 | AI15: =IF(AH15="","",SQRT(AH15)) -> 0.28926049 | AJ15: =IF(AI15="","",AG15-1.96*AI15) -> -1.0102188 | AK15: =IF(AI15="","",AG15+1.96*AI15) -> 0.12368233 | AL15: =IF(AI15="","",AG15/AI15) -> -1.5324189 | AM15: =IF(AL15="","",2*(1-NORMSDIST(ABS(AL15)))) -> 0.1254191 | AN15: =IF(COUNT(V15)=0,"",IF(AB15="t_paired",V15,V15+N(Y15))) -> 49 | AO15: =IF(AH15="","",1/AH15) -> 11.951482 | AP15: N | AQ15: Extracted from uploaded paper (replaces rows in your workbook(s): WB2) | AR15: Table 1 baseline. NB: your curiosity workbook entered these baseline values as Post-test | AS15: =IF(AND(AP15="Y",ISNUMBER(AO15)),AO15,0) -> 0 | AT15: =IF(AS15>0,AS15*AG15,0) -> 0 | AU15: =IF(AS15>0,AS15*AG15^2,0) -> 0 | AV15: =IF(AS15>0,AS15^2,0) -> 0 | AW15: =IF(AS15>0,AG15,0) -> 0 | AX15: =IF(AS15>0,AH15,1) -> 1
A16: ES015 | B16: S003 | C16: Ali et al. (2021) | D16: 2021 | E16: United States | F16: Primary education (inferred from title) | G16: Not reported in source workbook | H16: AI educational robot | I16: AI educational robot | J16: Not reported | K16: Two-group comparison (per source workbook; verify design) | L16: Control group (per source workbook) | O16: Not reported | P16: Cognitive | Q16: Higher-order thinking skills | S16: Figural creativity | T16: TCT-DP | U16: Post-test | V16: 34 | W16: 32.88 | X16: 9.64 | Y16: 33 | Z16: 27.75 | AA16: 11.11 | AB16: MSD | AD16: 1 | AE16: =IFERROR(IF(AB16="MSD",IF(COUNT(V16,W16,X16,Y16,Z16,AA16)<6,"",(W16-Z16)/SQRT(((V16-1)*X16^2+(Y16-1)*AA16^2)/(V16+Y16-2))*AD16),IF(AB16="t",AC16*SQRT(1/V16+1/Y16)*AD16,IF(AB16="F",SQRT(AC16)*SQRT(1/V16+1/Y16)*AD16,IF(AB16="z",2*(AC16/SQRT(V16+Y16))/SQRT(1-(AC16/SQRT(V16+Y16))^2)*AD16,IF(AB16="t_paired",AC16/SQRT(V16)*AD16,""))))),"") -> 0.49375744 | AF16: =IF(AE16="","",IF(AB16="t_paired",1-3/(4*(V16-1)-1),1-3/(4*(V16+Y16)-9))) -> 0.98841699 | AG16: =IF(AE16="","",AE16*AF16) -> 0.48803824 | AH16: =IF(AG16="","",IF(AB16="t_paired",1/V16+AG16^2/(2*V16),(V16+Y16)/(V16*Y16)+AG16^2/(2*(V16+Y16)))) -> 0.061492268 | AI16: =IF(AH16="","",SQRT(AH16)) -> 0.24797634 | AJ16: =IF(AI16="","",AG16-1.96*AI16) -> 0.0020046084 | AK16: =IF(AI16="","",AG16+1.96*AI16) -> 0.97407188 | AL16: =IF(AI16="","",AG16/AI16) -> 1.9680839 | AM16: =IF(AL16="","",2*(1-NORMSDIST(ABS(AL16)))) -> 0.049058389 | AN16: =IF(COUNT(V16)=0,"",IF(AB16="t_paired",V16,V16+N(Y16))) -> 67 | AO16: =IF(AH16="","",1/AH16) -> 16.262207 | AP16: Y | AQ16: Raw_Data_ES_Meta_Analysis_Study_2.xlsx | AS16: =IF(AND(AP16="Y",ISNUMBER(AO16)),AO16,0) -> 16.262207 | AT16: =IF(AS16>0,AS16*AG16,0) -> 7.9365791 | AU16: =IF(AS16>0,AS16*AG16^2,0) -> 3.8733541 | AV16: =IF(AS16>0,AS16^2,0) -> 264.45938 | AW16: =IF(AS16>0,AG16,0) -> 0.48803824 | AX16: =IF(AS16>0,AH16,1) -> 0.061492268
A17: ES016 | B17: S003 | C17: Ali et al. (2021) | D17: 2021 | E17: United States | F17: Primary education (inferred from title) | G17: Not reported in source workbook | H17: AI educational robot | I17: AI educational robot | J17: Not reported | K17: Two-group comparison (per source workbook; verify design) | L17: Control group (per source workbook) | O17: Not reported | P17: Cognitive | Q17: Higher-order thinking skills | S17: Verbal creativity | T17: TCT-DP | U17: Post-test | V17: 33 | W17: 42.27 | X17: 14.3 | Y17: 34 | Z17: 32.88 | AA17: 9.64 | AB17: MSD | AD17: 1 | AE17: =IFERROR(IF(AB17="MSD",IF(COUNT(V17,W17,X17,Y17,Z17,AA17)<6,"",(W17-Z17)/SQRT(((V17-1)*X17^2+(Y17-1)*AA17^2)/(V17+Y17-2))*AD17),IF(AB17="t",AC17*SQRT(1/V17+1/Y17)*AD17,IF(AB17="F",SQRT(AC17)*SQRT(1/V17+1/Y17)*AD17,IF(AB17="z",2*(AC17/SQRT(V17+Y17))/SQRT(1-(AC17/SQRT(V17+Y17))^2)*AD17,IF(AB17="t_paired",AC17/SQRT(V17)*AD17,""))))),"") -> 0.77224039 | AF17: =IF(AE17="","",IF(AB17="t_paired",1-3/(4*(V17-1)-1),1-3/(4*(V17+Y17)-9))) -> 0.98841699 | AG17: =IF(AE17="","",AE17*AF17) -> 0.76329552 | AH17: =IF(AG17="","",IF(AB17="t_paired",1/V17+AG17^2/(2*V17),(V17+Y17)/(V17*Y17)+AG17^2/(2*(V17+Y17)))) -> 0.064062706 | AI17: =IF(AH17="","",SQRT(AH17)) -> 0.25310612 | AJ17: =IF(AI17="","",AG17-1.96*AI17) -> 0.26720754 | AK17: =IF(AI17="","",AG17+1.96*AI17) -> 1.2593835 | AL17: =IF(AI17="","",AG17/AI17) -> 3.0157135 | AM17: =IF(AL17="","",2*(1-NORMSDIST(ABS(AL17)))) -> 0.002563754 | AN17: =IF(COUNT(V17)=0,"",IF(AB17="t_paired",V17,V17+N(Y17))) -> 67 | AO17: =IF(AH17="","",1/AH17) -> 15.609706 | AP17: Y | AQ17: Raw_Data_ES_Meta_Analysis_Study_2.xlsx | AS17: =IF(AND(AP17="Y",ISNUMBER(AO17)),AO17,0) -> 15.609706 | AT17: =IF(AS17>0,AS17*AG17,0) -> 11.914819 | AU17: =IF(AS17>0,AS17*AG17^2,0) -> 9.0945278 | AV17: =IF(AS17>0,AS17^2,0) -> 243.66292 | AW17: =IF(AS17>0,AG17,0) -> 0.76329552 | AX17: =IF(AS17>0,AH17,1) -> 0.064062706
A18: ES017 | B18: S004 | C18: Ausin et al. (2023) | D18: 2023 | E18: United States | F18: Higher education | G18: Not reported in source workbook | H18: Intelligent tutoring / adaptive learning AI | I18: Reinforcement Learning (RL) | J18: Not reported | K18: Two-group comparison (per source workbook; verify design) | L18: Control group (per source workbook) | O18: Not reported | P18: Cognitive | Q18: Higher-order thinking skills | S18: Students' Performance (Experiment 1) | T18: Problem-solving ability tests | U18: Post-test | V18: 41 | W18: 48.6 | X18: 22.7 | Y18: 43 | Z18: 54 | AA18: 18.3 | AB18: MSD | AD18: 1 | AE18: =IFERROR(IF(AB18="MSD",IF(COUNT(V18,W18,X18,Y18,Z18,AA18)<6,"",(W18-Z18)/SQRT(((V18-1)*X18^2+(Y18-1)*AA18^2)/(V18+Y18-2))*AD18),IF(AB18="t",AC18*SQRT(1/V18+1/Y18)*AD18,IF(AB18="F",SQRT(AC18)*SQRT(1/V18+1/Y18)*AD18,IF(AB18="z",2*(AC18/SQRT(V18+Y18))/SQRT(1-(AC18/SQRT(V18+Y18))^2)*AD18,IF(AB18="t_paired",AC18/SQRT(V18)*AD18,""))))),"") -> -0.26259113 | AF18: =IF(AE18="","",IF(AB18="t_paired",1-3/(4*(V18-1)-1),1-3/(4*(V18+Y18)-9))) -> 0.99082569 | AG18: =IF(AE18="","",AE18*AF18) -> -0.26018204 | AH18: =IF(AG18="","",IF(AB18="t_paired",1/V18+AG18^2/(2*V18),(V18+Y18)/(V18*Y18)+AG18^2/(2*(V18+Y18)))) -> 0.048049002 | AI18: =IF(AH18="","",SQRT(AH18)) -> 0.21920083 | AJ18: =IF(AI18="","",AG18-1.96*AI18) -> -0.68981566 | AK18: =IF(AI18="","",AG18+1.96*AI18) -> 0.16945158 | AL18: =IF(AI18="","",AG18/AI18) -> -1.1869574 | AM18: =IF(AL18="","",2*(1-NORMSDIST(ABS(AL18)))) -> 0.23524444 | AN18: =IF(COUNT(V18)=0,"",IF(AB18="t_paired",V18,V18+N(Y18))) -> 84 | AO18: =IF(AH18="","",1/AH18) -> 20.812087 | AP18: Y | AQ18: Very_New_Cognitive_Higher_Edcn_Effect_Size.xlsx | AR18: Same data also in WB5: 'Outcome' (uncoded) | AS18: =IF(AND(AP18="Y",ISNUMBER(AO18)),AO18,0) -> 20.812087 | AT18: =IF(AS18>0,AS18*AG18,0) -> -5.4149311 | AU18: =IF(AS18>0,AS18*AG18^2,0) -> 1.4088678 | AV18: =IF(AS18>0,AS18^2,0) -> 433.14295 | AW18: =IF(AS18>0,AG18,0) -> -0.26018204 | AX18: =IF(AS18>0,AH18,1) -> 0.048049002
A19: ES018 | B19: S004 | C19: Ausin et al. (2023) | D19: 2023 | E19: United States | F19: Higher education | G19: Not reported in source workbook | H19: Intelligent tutoring / adaptive learning AI | I19: Reinforcement Learning (RL) | J19: Not reported | K19: Two-group comparison (per source workbook; verify design) | L19: Control group (per source workbook) | O19: Not reported | P19: Cognitive | Q19: Higher-order thinking skills | S19: Students' Performance (Experiment 2) | T19: Problem-solving ability tests | U19: Post-test | V19: 30 | W19: 29.44 | X19: 16.43 | Y19: 23 | Z19: 41.61 | AA19: 25.07 | AB19: MSD | AD19: 1 | AE19: =IFERROR(IF(AB19="MSD",IF(COUNT(V19,W19,X19,Y19,Z19,AA19)<6,"",(W19-Z19)/SQRT(((V19-1)*X19^2+(Y19-1)*AA19^2)/(V19+Y19-2))*AD19),IF(AB19="t",AC19*SQRT(1/V19+1/Y19)*AD19,IF(AB19="F",SQRT(AC19)*SQRT(1/V19+1/Y19)*AD19,IF(AB19="z",2*(AC19/SQRT(V19+Y19))/SQRT(1-(AC19/SQRT(V19+Y19))^2)*AD19,IF(AB19="t_paired",AC19/SQRT(V19)*AD19,""))))),"") -> -0.5905973 | AF19: =IF(AE19="","",IF(AB19="t_paired",1-3/(4*(V19-1)-1),1-3/(4*(V19+Y19)-9))) -> 0.98522167 | AG19: =IF(AE19="","",AE19*AF19) -> -0.58186926 | AH19: =IF(AG19="","",IF(AB19="t_paired",1/V19+AG19^2/(2*V19),(V19+Y19)/(V19*Y19)+AG19^2/(2*(V19+Y19)))) -> 0.080005668 | AI19: =IF(AH19="","",SQRT(AH19)) -> 0.28285273 | AJ19: =IF(AI19="","",AG19-1.96*AI19) -> -1.1362606 | AK19: =IF(AI19="","",AG19+1.96*AI19) -> -0.027477909 | AL19: =IF(AI19="","",AG19/AI19) -> -2.0571456 | AM19: =IF(AL19="","",2*(1-NORMSDIST(ABS(AL19)))) -> 0.039672219 | AN19: =IF(COUNT(V19)=0,"",IF(AB19="t_paired",V19,V19+N(Y19))) -> 53 | AO19: =IF(AH19="","",1/AH19) -> 12.499114 | AP19: Y | AQ19: Very_New_Cognitive_Higher_Edcn_Effect_Size.xlsx | AR19: Same data also in WB5: 'Students' Perormance' (uncoded) | AS19: =IF(AND(AP19="Y",ISNUMBER(AO19)),AO19,0) -> 12.499114 | AT19: =IF(AS19>0,AS19*AG19,0) -> -7.2728505 | AU19: =IF(AS19>0,AS19*AG19^2,0) -> 4.2318482 | AV19: =IF(AS19>0,AS19^2,0) -> 156.22786 | AW19: =IF(AS19>0,AG19,0) -> -0.58186926 | AX19: =IF(AS19>0,AH19,1) -> 0.080005668
A20: ES019 | B20: S005 | C20: Bachiri et al. (2023) | D20: 2023 | E20: Morocco | F20: Primary education | G20: STEM | H20: Generative AI (LLM-based) | I20: Generative AI | J20: Yes | K20: Two-group comparison (per source workbook; verify design) | L20: Control group (per source workbook) | M20: 3 | O20: 1 week to 1 month | P20: Cognitive | Q20: Skill-based outcome | S20: Learning engagement | T20: Automatic Questions Generation method | U20: Pre-test | V20: 50 | W20: 70.5 | X20: 7.8 | Y20: 50 | Z20: 70.1 | AA20: 8.2 | AB20: MSD | AD20: 1 | AE20: =IFERROR(IF(AB20="MSD",IF(COUNT(V20,W20,X20,Y20,Z20,AA20)<6,"",(W20-Z20)/SQRT(((V20-1)*X20^2+(Y20-1)*AA20^2)/(V20+Y20-2))*AD20),IF(AB20="t",AC20*SQRT(1/V20+1/Y20)*AD20,IF(AB20="F",SQRT(AC20)*SQRT(1/V20+1/Y20)*AD20,IF(AB20="z",2*(AC20/SQRT(V20+Y20))/SQRT(1-(AC20/SQRT(V20+Y20))^2)*AD20,IF(AB20="t_paired",AC20/SQRT(V20)*AD20,""))))),"") -> 0.049984382 | AF20: =IF(AE20="","",IF(AB20="t_paired",1-3/(4*(V20-1)-1),1-3/(4*(V20+Y20)-9))) -> 0.99232737 | AG20: =IF(AE20="","",AE20*AF20) -> 0.04960087 | AH20: =IF(AG20="","",IF(AB20="t_paired",1/V20+AG20^2/(2*V20),(V20+Y20)/(V20*Y20)+AG20^2/(2*(V20+Y20)))) -> 0.040012301 | AI20: =IF(AH20="","",SQRT(AH20)) -> 0.20003075 | AJ20: =IF(AI20="","",AG20-1.96*AI20) -> -0.3424594 | AK20: =IF(AI20="","",AG20+1.96*AI20) -> 0.44166114 | AL20: =IF(AI20="","",AG20/AI20) -> 0.24796623 | AM20: =IF(AL20="","",2*(1-NORMSDIST(ABS(AL20)))) -> 0.80416054 | AN20: =IF(COUNT(V20)=0,"",IF(AB20="t_paired",V20,V20+N(Y20))) -> 100 | AO20: =IF(AH20="","",1/AH20) -> 24.992314 | AP20: N | AQ20: Raw_Data_ES_Meta_Analysis_Study_2.xlsx | AR20: Same data also in WB2: 'Intrinsic motivation' (Curiosity; Epistemic curiosity) | AS20: =IF(AND(AP20="Y",ISNUMBER(AO20)),AO20,0) -> 0 | AT20: =IF(AS20>0,AS20*AG20,0) -> 0 | AU20: =IF(AS20>0,AS20*AG20^2,0) -> 0 | AV20: =IF(AS20>0,AS20^2,0) -> 0 | AW20: =IF(AS20>0,AG20,0) -> 0 | AX20: =IF(AS20>0,AH20,1) -> 1
A21: ES020 | B21: S005 | C21: Bachiri et al. (2023) | D21: 2023 | E21: Morocco | F21: Primary education | G21: STEM | H21: Generative AI (LLM-based) | I21: Generative AI | J21: Yes | K21: Two-group comparison (per source workbook; verify design) | L21: Control group (per source workbook) | M21: 3 | O21: 1 week to 1 month | P21: Cognitive | Q21: Skill-based outcome | S21: Learning engagement | T21: Automatic Questions Generation method | U21: Post-test | V21: 50 | W21: 85.4 | X21: 5.6 | Y21: 50 | Z21: 76.3 | AA21: 7.9 | AB21: MSD | AD21: 1 | AE21: =IFERROR(IF(AB21="MSD",IF(COUNT(V21,W21,X21,Y21,Z21,AA21)<6,"",(W21-Z21)/SQRT(((V21-1)*X21^2+(Y21-1)*AA21^2)/(V21+Y21-2))*AD21),IF(AB21="t",AC21*SQRT(1/V21+1/Y21)*AD21,IF(AB21="F",SQRT(AC21)*SQRT(1/V21+1/Y21)*AD21,IF(AB21="z",2*(AC21/SQRT(V21+Y21))/SQRT(1-(AC21/SQRT(V21+Y21))^2)*AD21,IF(AB21="t_paired",AC21/SQRT(V21)*AD21,""))))),"") -> 1.3289983 | AF21: =IF(AE21="","",IF(AB21="t_paired",1-3/(4*(V21-1)-1),1-3/(4*(V21+Y21)-9))) -> 0.99232737 | AG21: =IF(AE21="","",AE21*AF21) -> 1.3188014 | AH21: =IF(AG21="","",IF(AB21="t_paired",1/V21+AG21^2/(2*V21),(V21+Y21)/(V21*Y21)+AG21^2/(2*(V21+Y21)))) -> 0.048696186 | AI21: =IF(AH21="","",SQRT(AH21)) -> 0.22067212 | AJ21: =IF(AI21="","",AG21-1.96*AI21) -> 0.88628404 | AK21: =IF(AI21="","",AG21+1.96*AI21) -> 1.7513188 | AL21: =IF(AI21="","",AG21/AI21) -> 5.9762936 | AM21: =IF(AL21="","",2*(1-NORMSDIST(ABS(AL21)))) -> 2.2827138e-09 | AN21: =IF(COUNT(V21)=0,"",IF(AB21="t_paired",V21,V21+N(Y21))) -> 100 | AO21: =IF(AH21="","",1/AH21) -> 20.535489 | AP21: Y | AQ21: Raw_Data_ES_Meta_Analysis_Study_2.xlsx | AR21: Same data also in WB2: 'Intrinsic motivation' (Curiosity; Epistemic curiosity) | AS21: =IF(AND(AP21="Y",ISNUMBER(AO21)),AO21,0) -> 20.535489 | AT21: =IF(AS21>0,AS21*AG21,0) -> 27.082232 | AU21: =IF(AS21>0,AS21*AG21^2,0) -> 35.716086 | AV21: =IF(AS21>0,AS21^2,0) -> 421.70632 | AW21: =IF(AS21>0,AG21,0) -> 1.3188014 | AX21: =IF(AS21>0,AH21,1) -> 0.048696186
A22: ES021 | B22: S006 | C22: Baha et al. (2023) | D22: 2023 | E22: Morocco | F22: Not reported in source workbook (verify) | G22: Not reported in source workbook | H22: Conversational AI / chatbot | I22: Chatbot | J22: Not reported | K22: Two-group comparison (per source workbook; verify design) | L22: Control group (per source workbook) | N22: 120 | O22: Not reported | P22: Cognitive | Q22: Knowledge-based outcome | S22: Learning gain | T22: Quiz | U22: Post-test | V22: 34 | W22: 10.97 | X22: 4.03 | Y22: 38 | Z22: 10.5 | AA22: 3.34 | AB22: MSD | AD22: 1 | AE22: =IFERROR(IF(AB22="MSD",IF(COUNT(V22,W22,X22,Y22,Z22,AA22)<6,"",(W22-Z22)/SQRT(((V22-1)*X22^2+(Y22-1)*AA22^2)/(V22+Y22-2))*AD22),IF(AB22="t",AC22*SQRT(1/V22+1/Y22)*AD22,IF(AB22="F",SQRT(AC22)*SQRT(1/V22+1/Y22)*AD22,IF(AB22="z",2*(AC22/SQRT(V22+Y22))/SQRT(1-(AC22/SQRT(V22+Y22))^2)*AD22,IF(AB22="t_paired",AC22/SQRT(V22)*AD22,""))))),"") -> 0.12766765 | AF22: =IF(AE22="","",IF(AB22="t_paired",1-3/(4*(V22-1)-1),1-3/(4*(V22+Y22)-9))) -> 0.98924731 | AG22: =IF(AE22="","",AE22*AF22) -> 0.12629487 | AH22: =IF(AG22="","",IF(AB22="t_paired",1/V22+AG22^2/(2*V22),(V22+Y22)/(V22*Y22)+AG22^2/(2*(V22+Y22)))) -> 0.055838321 | AI22: =IF(AH22="","",SQRT(AH22)) -> 0.23630133 | AJ22: =IF(AI22="","",AG22-1.96*AI22) -> -0.33685574 | AK22: =IF(AI22="","",AG22+1.96*AI22) -> 0.58944549 | AL22: =IF(AI22="","",AG22/AI22) -> 0.53446535 | AM22: =IF(AL22="","",2*(1-NORMSDIST(ABS(AL22)))) -> 0.59301962 | AN22: =IF(COUNT(V22)=0,"",IF(AB22="t_paired",V22,V22+N(Y22))) -> 72 | AO22: =IF(AH22="","",1/AH22) -> 17.908848 | AP22: Y | AQ22: Raw_Data_ES_Meta_Analysis_Study_2.xlsx | AS22: =IF(AND(AP22="Y",ISNUMBER(AO22)),AO22,0) -> 17.908848 | AT22: =IF(AS22>0,AS22*AG22,0) -> 2.2617957 | AU22: =IF(AS22>0,AS22*AG22^2,0) -> 0.28565321 | AV22: =IF(AS22>0,AS22^2,0) -> 320.72684 | AW22: =IF(AS22>0,AG22,0) -> 0.12629487 | AX22: =IF(AS22>0,AH22,1) -> 0.055838321
A23: ES022 | B23: S007 | C23: Chang et al. (2022) | D23: 2022 | E23: Taiwan | F23: Higher education | G23: Not reported in source workbook | H23: Conversational AI / chatbot | I23: Conversational AI | J23: Not reported | K23: Two-group comparison (per source workbook; verify design) | L23: Control group (per source workbook) | M23: 1(4) | N23: 50 | O23: 1 week to 1 month | P23: Cognitive | Q23: Higher-order thinking skills | S23: Critical thinking | U23: Post-test | V23: 16 | W23: 4.07 | X23: 0.65 | Y23: 16 | Z23: 2.83 | AA23: 0.68 | AB23: MSD | AD23: 1 | AE23: =IFERROR(IF(AB23="MSD",IF(COUNT(V23,W23,X23,Y23,Z23,AA23)<6,"",(W23-Z23)/SQRT(((V23-1)*X23^2+(Y23-1)*AA23^2)/(V23+Y23-2))*AD23),IF(AB23="t",AC23*SQRT(1/V23+1/Y23)*AD23,IF(AB23="F",SQRT(AC23)*SQRT(1/V23+1/Y23)*AD23,IF(AB23="z",2*(AC23/SQRT(V23+Y23))/SQRT(1-(AC23/SQRT(V23+Y23))^2)*AD23,IF(AB23="t_paired",AC23/SQRT(V23)*AD23,""))))),"") -> 1.8641875 | AF23: =IF(AE23="","",IF(AB23="t_paired",1-3/(4*(V23-1)-1),1-3/(4*(V23+Y23)-9))) -> 0.97478992 | AG23: =IF(AE23="","",AE23*AF23) -> 1.8171912 | AH23: =IF(AG23="","",IF(AB23="t_paired",1/V23+AG23^2/(2*V23),(V23+Y23)/(V23*Y23)+AG23^2/(2*(V23+Y23)))) -> 0.17659662 | AI23: =IF(AH23="","",SQRT(AH23)) -> 0.42023401 | AJ23: =IF(AI23="","",AG23-1.96*AI23) -> 0.9935325 | AK23: =IF(AI23="","",AG23+1.96*AI23) -> 2.6408498 | AL23: =IF(AI23="","",AG23/AI23) -> 4.3242363 | AM23: =IF(AL23="","",2*(1-NORMSDIST(ABS(AL23)))) -> 1.5306116e-05 | AN23: =IF(COUNT(V23)=0,"",IF(AB23="t_paired",V23,V23+N(Y23))) -> 32 | AO23: =IF(AH23="","",1/AH23) -> 5.6626225 | AP23: Y | AQ23: E.S_File_Meta_Analysis_.xlsx | AS23: =IF(AND(AP23="Y",ISNUMBER(AO23)),AO23,0) -> 5.6626225 | AT23: =IF(AS23>0,AS23*AG23,0) -> 10.290068 | AU23: =IF(AS23>0,AS23*AG23^2,0) -> 18.69902 | AV23: =IF(AS23>0,AS23^2,0) -> 32.065294 | AW23: =IF(AS23>0,AG23,0) -> 1.8171912 | AX23: =IF(AS23>0,AH23,1) -> 0.17659662
A24: ES023 | B24: S007 | C24: Chang et al. (2022) | D24: 2022 | E24: Taiwan | F24: Higher education | G24: Not reported in source workbook | H24: Conversational AI / chatbot | I24: Conversational AI | J24: Not reported | K24: Two-group comparison (per source workbook; verify design) | L24: Control group (per source workbook) | M24: 1(4) | N24: 50 | O24: 1 week to 1 month | P24: Cognitive | Q24: Knowledge-based outcome | S24: Learning achievement | T24: Achievement test | U24: Post-test | V24: 16 | W24: 87.9 | X24: 11.3 | Y24: 16 | Z24: 62.32 | AA24: 14.95 | AB24: MSD | AD24: 1 | AE24: =IFERROR(IF(AB24="MSD",IF(COUNT(V24,W24,X24,Y24,Z24,AA24)<6,"",(W24-Z24)/SQRT(((V24-1)*X24^2+(Y24-1)*AA24^2)/(V24+Y24-2))*AD24),IF(AB24="t",AC24*SQRT(1/V24+1/Y24)*AD24,IF(AB24="F",SQRT(AC24)*SQRT(1/V24+1/Y24)*AD24,IF(AB24="z",2*(AC24/SQRT(V24+Y24))/SQRT(1-(AC24/SQRT(V24+Y24))^2)*AD24,IF(AB24="t_paired",AC24/SQRT(V24)*AD24,""))))),"") -> 1.9303805 | AF24: =IF(AE24="","",IF(AB24="t_paired",1-3/(4*(V24-1)-1),1-3/(4*(V24+Y24)-9))) -> 0.97478992 | AG24: =IF(AE24="","",AE24*AF24) -> 1.8817154 | AH24: =IF(AG24="","",IF(AB24="t_paired",1/V24+AG24^2/(2*V24),(V24+Y24)/(V24*Y24)+AG24^2/(2*(V24+Y24)))) -> 0.18032583 | AI24: =IF(AH24="","",SQRT(AH24)) -> 0.42464789 | AJ24: =IF(AI24="","",AG24-1.96*AI24) -> 1.0494056 | AK24: =IF(AI24="","",AG24+1.96*AI24) -> 2.7140253 | AL24: =IF(AI24="","",AG24/AI24) -> 4.431237 | AM24: =IF(AL24="","",2*(1-NORMSDIST(ABS(AL24)))) -> 9.3694026e-06 | AN24: =IF(COUNT(V24)=0,"",IF(AB24="t_paired",V24,V24+N(Y24))) -> 32 | AO24: =IF(AH24="","",1/AH24) -> 5.5455173 | AP24: Y | AQ24: Very_New_Cognitive_Higher_Edcn_Effect_Size.xlsx | AR24: Same data also in WB5: 'Learning achievement' (uncoded) | AS24: =IF(AND(AP24="Y",ISNUMBER(AO24)),AO24,0) -> 5.5455173 | AT24: =IF(AS24>0,AS24*AG24,0) -> 10.435086 | AU24: =IF(AS24>0,AS24*AG24^2,0) -> 19.635862 | AV24: =IF(AS24>0,AS24^2,0) -> 30.752762 | AW24: =IF(AS24>0,AG24,0) -> 1.8817154 | AX24: =IF(AS24>0,AH24,1) -> 0.18032583
A25: ES024 | B25: S008 | C25: Chang et al. (2022) | D25: 2022 | E25: Taiwan | F25: Higher education | G25: Not reported in source workbook | H25: Conversational AI / chatbot | I25: Conversational AI | J25: Not reported | K25: Two-group comparison (per source workbook; verify design) | L25: Control group (per source workbook) | M25: 2 | N25: 200 | O25: 1 week to 1 month | P25: Cognitive | Q25: Knowledge-based outcome | S25: Learning achievement | T25: Knowledge test | U25: Post-test | V25: 18 | W25: 88.58 | X25: 11.02 | Y25: 18 | Z25: 60.51 | AA25: 15.01 | AB25: MSD | AD25: 1 | AE25: =IFERROR(IF(AB25="MSD",IF(COUNT(V25,W25,X25,Y25,Z25,AA25)<6,"",(W25-Z25)/SQRT(((V25-1)*X25^2+(Y25-1)*AA25^2)/(V25+Y25-2))*AD25),IF(AB25="t",AC25*SQRT(1/V25+1/Y25)*AD25,IF(AB25="F",SQRT(AC25)*SQRT(1/V25+1/Y25)*AD25,IF(AB25="z",2*(AC25/SQRT(V25+Y25))/SQRT(1-(AC25/SQRT(V25+Y25))^2)*AD25,IF(AB25="t_paired",AC25/SQRT(V25)*AD25,""))))),"") -> 2.1318425 | AF25: =IF(AE25="","",IF(AB25="t_paired",1-3/(4*(V25-1)-1),1-3/(4*(V25+Y25)-9))) -> 0.97777778 | AG25: =IF(AE25="","",AE25*AF25) -> 2.0844683 | AH25: =IF(AG25="","",IF(AB25="t_paired",1/V25+AG25^2/(2*V25),(V25+Y25)/(V25*Y25)+AG25^2/(2*(V25+Y25)))) -> 0.17145844 | AI25: =IF(AH25="","",SQRT(AH25)) -> 0.41407541 | AJ25: =IF(AI25="","",AG25-1.96*AI25) -> 1.2728805 | AK25: =IF(AI25="","",AG25+1.96*AI25) -> 2.8960561 | AL25: =IF(AI25="","",AG25/AI25) -> 5.0340306 | AM25: =IF(AL25="","",2*(1-NORMSDIST(ABS(AL25)))) -> 4.8027302e-07 | AN25: =IF(COUNT(V25)=0,"",IF(AB25="t_paired",V25,V25+N(Y25))) -> 36 | AO25: =IF(AH25="","",1/AH25) -> 5.832317 | AP25: Y | AQ25: Very_New_Cognitive_Higher_Edcn_Effect_Size.xlsx | AR25: Same data also in WB5: 'Learning achievement' (uncoded) | AS25: =IF(AND(AP25="Y",ISNUMBER(AO25)),AO25,0) -> 5.832317 | AT25: =IF(AS25>0,AS25*AG25,0) -> 12.15728 | AU25: =IF(AS25>0,AS25*AG25^2,0) -> 25.341464 | AV25: =IF(AS25>0,AS25^2,0) -> 34.015922 | AW25: =IF(AS25>0,AG25,0) -> 2.0844683 | AX25: =IF(AS25>0,AH25,1) -> 0.17145844
A26: ES025 | B26: S009 | C26: Chen and Chang (2024) | D26: 2024 | E26: China | F26: Secondary education | G26: STEM | H26: Generative AI (LLM-based) | I26: Generative AI | J26: No | K26: Two-group comparison (per source workbook; verify design) | L26: Control group (per source workbook) | M26: 2 (10) | N26: 60 | O26: 1 week to 1 month | P26: Cognitive | Q26: Skill-based outcome | S26: Learning achievement | T26: Knowledge test | U26: Pre-test | V26: 69 | W26: 41.21 | X26: 12.14 | Y26: 70 | Z26: 41.78 | AA26: 13.52 | AB26: MSD | AD26: 1 | AE26: =IFERROR(IF(AB26="MSD",IF(COUNT(V26,W26,X26,Y26,Z26,AA26)<6,"",(W26-Z26)/SQRT(((V26-1)*X26^2+(Y26-1)*AA26^2)/(V26+Y26-2))*AD26),IF(AB26="t",AC26*SQRT(1/V26+1/Y26)*AD26,IF(AB26="F",SQRT(AC26)*SQRT(1/V26+1/Y26)*AD26,IF(AB26="z",2*(AC26/SQRT(V26+Y26))/SQRT(1-(AC26/SQRT(V26+Y26))^2)*AD26,IF(AB26="t_paired",AC26/SQRT(V26)*AD26,""))))),"") -> -0.04434566 | AF26: =IF(AE26="","",IF(AB26="t_paired",1-3/(4*(V26-1)-1),1-3/(4*(V26+Y26)-9))) -> 0.99451554 | AG26: =IF(AE26="","",AE26*AF26) -> -0.044102448 | AH26: =IF(AG26="","",IF(AB26="t_paired",1/V26+AG26^2/(2*V26),(V26+Y26)/(V26*Y26)+AG26^2/(2*(V26+Y26)))) -> 0.028785464 | AI26: =IF(AH26="","",SQRT(AH26)) -> 0.1696628 | AJ26: =IF(AI26="","",AG26-1.96*AI26) -> -0.37664153 | AK26: =IF(AI26="","",AG26+1.96*AI26) -> 0.28843663 | AL26: =IF(AI26="","",AG26/AI26) -> -0.25994177 | AM26: =IF(AL26="","",2*(1-NORMSDIST(ABS(AL26)))) -> 0.79490869 | AN26: =IF(COUNT(V26)=0,"",IF(AB26="t_paired",V26,V26+N(Y26))) -> 139 | AO26: =IF(AH26="","",1/AH26) -> 34.739756 | AP26: N | AQ26: Raw_Data_ES_Meta_Analysis_Study_2.xlsx | AS26: =IF(AND(AP26="Y",ISNUMBER(AO26)),AO26,0) -> 0 | AT26: =IF(AS26>0,AS26*AG26,0) -> 0 | AU26: =IF(AS26>0,AS26*AG26^2,0) -> 0 | AV26: =IF(AS26>0,AS26^2,0) -> 0 | AW26: =IF(AS26>0,AG26,0) -> 0 | AX26: =IF(AS26>0,AH26,1) -> 1
A27: ES026 | B27: S009 | C27: Chen and Chang (2024) | D27: 2024 | E27: China | F27: Secondary education | G27: STEM | H27: Generative AI (LLM-based) | I27: Generative AI | J27: No | K27: Two-group comparison (per source workbook; verify design) | L27: Control group (per source workbook) | M27: 2 (10) | N27: 60 | O27: 1 week to 1 month | P27: Cognitive | Q27: Skill-based outcome | S27: Learning achievement | T27: Knowledge test | U27: Post-test | V27: 69 | W27: 49.06 | X27: 13.82 | Y27: 70 | Z27: 44.46 | AA27: 13.64 | AB27: MSD | AD27: 1 | AE27: =IFERROR(IF(AB27="MSD",IF(COUNT(V27,W27,X27,Y27,Z27,AA27)<6,"",(W27-Z27)/SQRT(((V27-1)*X27^2+(Y27-1)*AA27^2)/(V27+Y27-2))*AD27),IF(AB27="t",AC27*SQRT(1/V27+1/Y27)*AD27,IF(AB27="F",SQRT(AC27)*SQRT(1/V27+1/Y27)*AD27,IF(AB27="z",2*(AC27/SQRT(V27+Y27))/SQRT(1-(AC27/SQRT(V27+Y27))^2)*AD27,IF(AB27="t_paired",AC27/SQRT(V27)*AD27,""))))),"") -> 0.33504161 | AF27: =IF(AE27="","",IF(AB27="t_paired",1-3/(4*(V27-1)-1),1-3/(4*(V27+Y27)-9))) -> 0.99451554 | AG27: =IF(AE27="","",AE27*AF27) -> 0.33320409 | AH27: =IF(AG27="","",IF(AB27="t_paired",1/V27+AG27^2/(2*V27),(V27+Y27)/(V27*Y27)+AG27^2/(2*(V27+Y27)))) -> 0.029177838 | AI27: =IF(AH27="","",SQRT(AH27)) -> 0.17081522 | AJ27: =IF(AI27="","",AG27-1.96*AI27) -> -0.0015937397 | AK27: =IF(AI27="","",AG27+1.96*AI27) -> 0.66800191 | AL27: =IF(AI27="","",AG27/AI27) -> 1.9506698 | AM27: =IF(AL27="","",2*(1-NORMSDIST(ABS(AL27)))) -> 0.051096338 | AN27: =IF(COUNT(V27)=0,"",IF(AB27="t_paired",V27,V27+N(Y27))) -> 139 | AO27: =IF(AH27="","",1/AH27) -> 34.272587 | AP27: Y | AQ27: Raw_Data_ES_Meta_Analysis_Study_2.xlsx | AS27: =IF(AND(AP27="Y",ISNUMBER(AO27)),AO27,0) -> 34.272587 | AT27: =IF(AS27>0,AS27*AG27,0) -> 11.419766 | AU27: =IF(AS27>0,AS27*AG27^2,0) -> 3.8051127 | AV27: =IF(AS27>0,AS27^2,0) -> 1174.6102 | AW27: =IF(AS27>0,AG27,0) -> 0.33320409 | AX27: =IF(AS27>0,AH27,1) -> 0.029177838
A28: ES027 | B28: S009 | C28: Chen and Chang (2024) | D28: 2024 | E28: China | F28: Secondary education | G28: STEM | H28: Generative AI (LLM-based) | I28: Generative AI | J28: No | K28: Two-group comparison (per source workbook; verify design) | L28: Control group (per source workbook) | M28: 2 (10) | N28: 60 | O28: 1 week to 1 month | P28: Non-cognitive | Q28: Curiosity | R28: Epistemic curiosity | S28: Interest | T28: Knowledge test | U28: Post-test | V28: 69 | W28: 2.69 | X28: 1.05 | Y28: 70 | Z28: 2.64 | AA28: 1.15 | AB28: MSD | AD28: 1 | AE28: =IFERROR(IF(AB28="MSD",IF(COUNT(V28,W28,X28,Y28,Z28,AA28)<6,"",(W28-Z28)/SQRT(((V28-1)*X28^2+(Y28-1)*AA28^2)/(V28+Y28-2))*AD28),IF(AB28="t",AC28*SQRT(1/V28+1/Y28)*AD28,IF(AB28="F",SQRT(AC28)*SQRT(1/V28+1/Y28)*AD28,IF(AB28="z",2*(AC28/SQRT(V28+Y28))/SQRT(1-(AC28/SQRT(V28+Y28))^2)*AD28,IF(AB28="t_paired",AC28/SQRT(V28)*AD28,""))))),"") -> 0.045392634 | AF28: =IF(AE28="","",IF(AB28="t_paired",1-3/(4*(V28-1)-1),1-3/(4*(V28+Y28)-9))) -> 0.99451554 | AG28: =IF(AE28="","",AE28*AF28) -> 0.04514368 | AH28: =IF(AG28="","",IF(AB28="t_paired",1/V28+AG28^2/(2*V28),(V28+Y28)/(V28*Y28)+AG28^2/(2*(V28+Y28)))) -> 0.028785799 | AI28: =IF(AH28="","",SQRT(AH28)) -> 0.16966378 | AJ28: =IF(AI28="","",AG28-1.96*AI28) -> -0.28739733 | AK28: =IF(AI28="","",AG28+1.96*AI28) -> 0.37768469 | AL28: =IF(AI28="","",AG28/AI28) -> 0.26607729 | AM28: =IF(AL28="","",2*(1-NORMSDIST(ABS(AL28)))) -> 0.79017968 | AN28: =IF(COUNT(V28)=0,"",IF(AB28="t_paired",V28,V28+N(Y28))) -> 139 | AO28: =IF(AH28="","",1/AH28) -> 34.739352 | AP28: Y | AQ28: Extracted_Data_AI_agents_Learner_curiosity.xlsx | AS28: =IF(AND(AP28="Y",ISNUMBER(AO28)),AO28,0) -> 34.739352 | AT28: =IF(AS28>0,AS28*AG28,0) -> 1.5682622 | AU28: =IF(AS28>0,AS28*AG28^2,0) -> 0.070797126 | AV28: =IF(AS28>0,AS28^2,0) -> 1206.8226 | AW28: =IF(AS28>0,AG28,0) -> 0.04514368 | AX28: =IF(AS28>0,AH28,1) -> 0.028785799
A29: ES028 | B29: S010 | C29: Chen and Liu (2024) | D29: 2024 | E29: China | F29: Secondary education | G29: STEM | H29: Conversational AI / chatbot | I29: Conversational AI | J29: Yes | K29: Two-group comparison (per source workbook; verify design) | L29: Control group (per source workbook) | M29: 2 | N29: 135 | O29: 1 week to 1 month | P29: Cognitive | Q29: Skill-based outcome | S29: Students’ performance | T29: Diagnostic Test | U29: Pre-test | V29: 41 | W29: 0.56 | X29: 0.84 | Y29: 40 | Z29: 0.55 | AA29: 0.87 | AB29: MSD | AD29: 1 | AE29: =IFERROR(IF(AB29="MSD",IF(COUNT(V29,W29,X29,Y29,Z29,AA29)<6,"",(W29-Z29)/SQRT(((V29-1)*X29^2+(Y29-1)*AA29^2)/(V29+Y29-2))*AD29),IF(AB29="t",AC29*SQRT(1/V29+1/Y29)*AD29,IF(AB29="F",SQRT(AC29)*SQRT(1/V29+1/Y29)*AD29,IF(AB29="z",2*(AC29/SQRT(V29+Y29))/SQRT(1-(AC29/SQRT(V29+Y29))^2)*AD29,IF(AB29="t_paired",AC29/SQRT(V29)*AD29,""))))),"") -> 0.011696704 | AF29: =IF(AE29="","",IF(AB29="t_paired",1-3/(4*(V29-1)-1),1-3/(4*(V29+Y29)-9))) -> 0.99047619 | AG29: =IF(AE29="","",AE29*AF29) -> 0.011585307 | AH29: =IF(AG29="","",IF(AB29="t_paired",1/V29+AG29^2/(2*V29),(V29+Y29)/(V29*Y29)+AG29^2/(2*(V29+Y29)))) -> 0.049391072 | AI29: =IF(AH29="","",SQRT(AH29)) -> 0.22224102 | AJ29: =IF(AI29="","",AG29-1.96*AI29) -> -0.4240071 | AK29: =IF(AI29="","",AG29+1.96*AI29) -> 0.44717771 | AL29: =IF(AI29="","",AG29/AI29) -> 0.05212947 | AM29: =IF(AL29="","",2*(1-NORMSDIST(ABS(AL29)))) -> 0.95842553 | AN29: =IF(COUNT(V29)=0,"",IF(AB29="t_paired",V29,V29+N(Y29))) -> 81 | AO29: =IF(AH29="","",1/AH29) -> 20.246574 | AP29: N | AQ29: Raw_Data_ES_Meta_Analysis_Study_2.xlsx | AS29: =IF(AND(AP29="Y",ISNUMBER(AO29)),AO29,0) -> 0 | AT29: =IF(AS29>0,AS29*AG29,0) -> 0 | AU29: =IF(AS29>0,AS29*AG29^2,0) -> 0 | AV29: =IF(AS29>0,AS29^2,0) -> 0 | AW29: =IF(AS29>0,AG29,0) -> 0 | AX29: =IF(AS29>0,AH29,1) -> 1
